Workbook

Sheet raw
A1: nengdara.hdr@gmail.com | B1: Abdul Rayhan Pradipta | D1: =IF(E1="","",COUNTIF(B:B,E1)) -> 1 | E1: Abdul Rayhan Pradipta | F1: VII Thalhah bin Ubaidillah | G1: Marwan Malik Ibrahim, S.Pd. | K1: Kode Guru | L1: Nama Guru | P1: VII Abu Bakar Ash-shiddiq | R1: No | S1: Nama | T1: NIPD | U1: JK | V1: NISN | W1: Tempat Lahir | X1: Tanggal Lahir | Y1: NIK | Z1: Agama | AA1: Alamat | AB1: Kecamatan | AC1: Kode Pos | AD1: HP | AE1: E-Mail | AF1: nama ayah | AG1: tahun lahir | AH1: nama ibu | AI1: tahun lahir | AJ1: kelas
A2: abhinayasyafiq19@gmail.com | B2: Abhinaya Syafiq Natadikara | D2: =IF(E2="","",COUNTIF(B:B,E2)) -> 1 | E2: Abhinaya Syafiq Natadikara | F2: VII Abu Bakar Ash-shiddiq | G2: Agus Sayyidul Ayyam, S.Pd. | K2: AKR | L2: Arai Kurnia Ramadhan | P2: Abu Bakar Ash-shiddiq | R2: 1 | S2: ABDUL RAYHAN PRADIPTA | T2: 2627065 | U2: L | V2: 0141066499 | W2: Payakumbuh | X2: 2014-04-15 | Y2: 1371041504140002 | Z2: Islam | AA2: Jl. Tubagus Ismail 1 No. 20 | AB2: Kec. Coblong | AC2: 40132 | AD2: 085263366388 | AF2: SYUKRA AL HAMDA | AG2: 1989 | AH2: DARA INDAH PERTIWI | AI2: 1990 | AJ2: 7 C
A3: abyazfauzil@gmail.com | B3: Abyaz Fauzil Firjatullah | D3: =IF(E3="","",COUNTIF(B:B,E3)) -> 2 | E3: Abyaz Fauzil Firjatullah | F3: VIII Umar bin Khattab | G3: Sabrina Niela Ni'ami, S.Pd. | K3: ASA | L3: Agus Sayyidul Ayyam, S.Pd. | R3: 2 | S3: Abhinaya Syafiq Natadikara | T3: 2627001 | U3: L | V3: 3149021359 | W3: Tangerang | X3: 2014-03-19 | Y3: 3671111903140002 | Z3: Islam | AA3: Jingga Residence Blok C 90 | AB3: Kec. Rancasari | AC3: 40286 | AD3: 082120163344 | AE3: Rawidya80@gmail.com | AF3: Mustika Natadikara | AG3: 1977 | AH3: Ratna Widyaningsih | AI3: 1980 | AJ3: 7 A
A4: samlordshilmi@gmail.com | B4: Abyaz Fauzil Firjatullah | D4: =IF(E4="","",COUNTIF(B:B,E4)) -> 1 | E4: Adam Avicii Adelard | F4: VII Thalhah bin Ubaidillah | G4: Sahri Fauzan, S.Pd. | K4: BSI | L4: Bunga Sarah Istiqomah, S.Ag. | P4: VII Ali bin Abi Thalib | R4: 3 | S4: Abyaz Fauzil Firjatullah | T4: 2526001 | U4: L | V4: 3126431912 | W4: Bandung | X4: 2012-05-28 | Y4: 3273222805120003 | Z4: Islam | AA4: Jl. Cijawura Hilir II no. 123 | AB4: Kec. Buahbatu | AC4: 40287 | AD4: 085315331984 | AF4: Muhammad Abdul Basir | AG4: 1984 | AH4: Yeye Fahrina Inayatillah | AI4: 1983 | AJ4: 8 A
A5: adam.avicii.adelard@gmail.com | B5: Adam Avicii Adelard | D5: =IF(E5="","",COUNTIF(B:B,E5)) -> 1 | E5: Adinda Fatimah Zahra | F5: VII Ali bin Abi Thalib | G5: Sabrina Niela Ni'ami, S.Pd. | K5: LNI | L5: Lespi Nurul Izati, S.Ag. | P5: VII Thalhah bin Ubaidillah | R5: 4 | S5: Adam Avicii Adelard | T5: 2627066 | U5: L | V5: 0138107714 | W5: Bandung | X5: 2013-11-13 | Y5: 3273121311130003 | Z5: Islam | AA5: Riung Purna 7 No.5 | AB5: Kec. Gedebage | AD5: 081223458582 | AF5: Yerry Octavianus | AG5: 1979 | AH5: Ratna Hartati | AI5: 1990 | AJ5: 7 C
A6: azzahra11022014@gmail.com | B6: Adinda Fatimah Zahra | D6: =IF(E6="","",COUNTIF(B:B,E6)) -> 1 | E6: Adreena Shabira | F6: VII Abu Bakar Ash-shiddiq | G6: Lespi Nurul izzati, S.Ag. | K6: MSW | L6: Mawar Sri Wahyuni, S.Pd. | P6: VIII Umar bin Khattab | R6: 5 | S6: Adinda Fatimah Zahra | T6: 2627033 | U6: P | V6: 3143690788 | W6: Semarang | X6: 2014-02-11 | Y6: 3271065102140002 | Z6: Islam | AA6: Komp. Baitussalam/DPRD Kav. 53 | AB6: Kec. Buahbatu | AC6: 40287 | AD6: 088809589821 | AE6: astrisia240883@gmail.com | AF6: FAISAL FAZRIAN | AG6: 1983 | AH6: ASTRISIA FITRIANI | AI6: 1983 | AJ6: 7 B
A7: adeemerqwee@gmail.com | B7: Admira Queensha Azzahra | D7: =IF(E7="","",COUNTIF(B:B,E7)) -> 2 | E7: Adzikra Athari Rinaldi | F7: VII Thalhah bin Ubaidillah | G7: Sahri Fauzan, S.Pd. | K7: ANN | L7: Annida Nurrohmah | P7: VIII Abdurrahman bin Auf | R7: 6 | S7: Adreena Shabira | T7: 2627002 | U7: P | V7: 3147257623 | W7: Bandung | X7: 2014-05-26 | Y7: 3273236605140001 | Z7: Islam | AA7: Jl. Merkuri Tengah VIII No. 7 | AB7: Kec. Rancasari | AC7: 40286 | AD7: 081398718345 | AF7: Adriansyah | AG7: 1980 | AH7: KUSMADINI SUHARTI | AI7: 1981 | AJ7: 7 A
A8: g3nt42007@gmail.com | B8: Adreena Shabira | D8: =IF(E8="","",COUNTIF(B:B,E8)) -> 1 | E8: Adziqa naufal qisya | F8: VII Thalhah bin Ubaidillah | G8: Agus Sayyidul Ayyam, S.Pd. | K8: SHF | L8: Sahri Fauzan, S.Pd. | P8: VIII Sa'ad Bin Abi Waqqash | R8: 7 | S8: Adzikra Athari Rinaldi | T8: 2627067 | U8: P | V8: 0133723976 | W8: Bandung | X8: 2013-12-07 | Y8: 3273234712130001 | Z8: Islam | AA8: Merkuri Selatan VII NO 6 | AB8: Kec. Rancasari | AC8: 40286 | AD8: 081297841323 | AE8: Niasintawati81@gmail.com | AF8: Aris Rinaldi | AG8: 1979 | AH8: Nia Sintawaty | AI8: 1981 | AJ8: 7 C
A9: arisrinaldi79@gmail.com | B9: Adzikra Athari Rinaldi | D9: =IF(E9="","",COUNTIF(B:B,E9)) -> 2 | E9: Afifa Syakira Muktisa | F9: VIII Sa'ad Bin Abi Waqqash | G9: Bunga Sarah Istiqomah, S.Ag. | K9: MNS | L9: Muhammad Nurrachman Satrio, S.Pd. | P9: IX Utsman bin Affan | R9: 8 | S9: Adziqa Naufal Qisya | T9: 2627068 | U9: L | V9: 0138471291 | W9: Cimahi | X9: 2013-09-28 | Y9: 3273132809130002 | Z9: Islam | AA9: jl pasir intan no 3D pasir pogor | AB9: Kec. Rancasari | AC9: 40613 | AD9: 08996005408 | AE9: rikaandrianiyogianto@gmail.com | AF9: Yoga Yogianto | AG9: 1985 | AH9: Rika Andriani | AI9: 1992 | AJ9: 7 C
A10: niasintawaty81@gmail.com | B10: Adzikra Athari Rinaldi | D10: =IF(E10="","",COUNTIF(B:B,E10)) -> 1 | E10: afifah naura Zafarani | F10: IX Utsman bin Affan | G10: Marwan Malik Ibrahim, S.Pd. | P10: IX Zubair bin Awwam | R10: 9 | S10: Afifa Syakira Muktisa | T10: 2526065 | U10: P | V10: 0128498183 | W10: Bandung | X10: 2012-03-27 | Y10: 3273236703120002 | Z10: Islam | AA10: Jl. Taman Saturnus II no. 5 | AB10: Kec. Rancasari | AC10: 40286 | AD10: 0895703171029 | AF10: Anggi Pramadhya Mukti Wardhana | AG10: 1985 | AH10: Annisa Hartani | AI10: 1985 | AJ10: 8 C
A11: rikaandrianiyogianto@gmail.com | B11: Adziqa naufal qisya | D11: =IF(E11="","",COUNTIF(B:B,E11)) -> 0 | E11: Afnan Maqil Kautsar | F11: IX Utsman bin Affan | G11: Bunga Sarah Istiqomah, S.Ag. | R11: 10 | S11: AFIFAH NAURA ZAFARANI | T11: 2425001 | U11: P | V11: 0126787257 | W11: Blitar | X11: 2012-04-08 | Y11: 3505184804120001 | Z11: Islam | AA11: KOMP.BEA CUKAI NO.40 JL.CIJAWURA GIRANG V SEKEJATI BANDUNG | AB11: Kec. Buahbatu | AD11: 08997474076 | AF11: IMAM SOLIKIN | AG11: 1988 | AH11: SISKA MAHARANI | AI11: 1989 | AJ11: 9 A
A12: afifa.muktisa@gmail.com | B12: Afifa Syakira Muktisa | D12: =IF(E12="","",COUNTIF(B:B,E12)) -> 2 | E12: Agta Malika Lapuri | F12: VIII Abdurrahman bin Auf | G12: Agus Sayyidul Ayyam, S.Pd. | R12: 11 | S12: AFNAN MAQIL KAUTSAR | T12: 2425063 | U12: L | V12: 0121695890 | W12: BANDUNG | X12: 2012-07-01 | Y12: 3273270107140002 | Z12: Islam | AA12: JL. CEMARA C.5 BUMI ADIPURA | AB12: Kec. Gedebage | AC12: 40295 | AF12: ASEP NAJMURROKHMAN | AG12: 1971 | AH12: MEGGIE CHAIRINA | AI12: 1974 | AJ12: 9 A
A13: sayyiddays1984@gmail.com | B13: Afifa Syakira Muktisa | D13: =IF(E13="","",COUNTIF(B:B,E13)) -> 0 | E13: Ahmad Satria Alfatih | F13: VII Thalhah bin Ubaidillah | G13: Agus Sayyidul Ayyam, S.Pd. | R13: 12 | S13: AGTA MALIKA LAPURI | T13: 2526033 | U13: P | V13: 3137745114 | W13: BANDUNG | X13: 2013-03-08 | Y13: 3273234803130001 | Z13: Islam | AA13: KOMPLEK BANYU BIRU BLOK N-10 | AB13: Kec. Rancasari | AC13: 40613 | AD13: 085720505208 | AF13: ANUGRAH NURRADITA | AG13: 1986 | AH13: SHEILA PUSPITA WULANDARI | AI13: 1988 | AJ13: 8 B
A14: afifah.naura2012@gmail.com | B14: afifah naura Zafarani | D14: =IF(E14="","",COUNTIF(B:B,E14)) -> 1 | E14: Aisyah Hayundya Putri Senna | F14: VIII Sa'ad Bin Abi Waqqash | G14: Bunga Sarah Istiqomah, S.Ag. | R14: 13 | S14: Ahmad Satria Alfatih | T14: 2627069 | U14: L | V14: 3133234422 | W14: Balikpapan | X14: 2013-09-14 | Y14: 3172021409131007 | Z14: Islam | AA14: Jl. Papanggo I GG. Apel No.23 | AB14: Kec. Rancasari | AC14: 40292 | AD14: 081320450230 | AF14: Bayu Suryo Kusumo | AG14: 1982 | AH14: Hanifah Sani SPT | AI14: 1982 | AJ14: 7 C
A15: agtamalika@gmail.com | B15: Agta Malika Lapuri | D15: =IF(E15="","",COUNTIF(B:B,E15)) -> 2 | E15: Akma Faizia Khaerunnisa | F15: IX Utsman bin Affan | G15: Bunga Sarah Istiqomah, S.Ag. | R15: 14 | S15: AISYAH HAYUNDYA PUTRI SENNA | T15: 2526066 | U15: P | V15: 3136158343 | W15: Pontianak | X15: 2013-01-31 | Y15: 6171067101130001 | Z15: Islam | AA15: Jl. Gedebage komp. Bumi Adipura cluster palem raya No. 7 | AB15: Kec. Gedebage | AC15: 40294 | AD15: 081329120120 | AE15: hayunieta@gmail.com | AF15: Seno widodo | AG15: 1978 | AH15: Hayunieta | AI15: 1980 | AJ15: 8 C
A16: sayyiddays1984@gmail.com | B16: Agta Malika Lapuri | D16: =IF(E16="","",COUNTIF(B:B,E16)) -> 1 | E16: Al Junno Arkaan Kyonando | F16: VII Abu Bakar Ash-shiddiq | G16: Arai kurnia Ramadhan | R16: 15 | S16: Akma Faizia Khaerunnisa | T16: 2425032 | U16: P | V16: 0124314004 | W16: Bandung | X16: 2012-07-17 | Y16: 3273235707120001 | Z16: Islam | AA16: JL.MARS SELATAN III NO.9 MANJAHLEGA BANDUNG | AB16: Kec. Rancasari | AD16: 081322042660 | AE16: ventizia2012@gmail.com | AF16: ERI FEBRIANA | AG16: 1976 | AH16: SUVENTI TURIATIN | AI16: 1977 | AJ16: 9 A
A17: aisyahputrisenna@gmail.com | B17: Aisyah Hayundya Putri Senna | D17: =IF(E17="","",COUNTIF(B:B,E17)) -> 1 | E17: Alana Aisha Fara | F17: VIII Sa'ad Bin Abi Waqqash | G17: Arai Kurnia Ramadhan | R17: 16 | S17: AL JUNNO ARKAAN KYONANDO | T17: 2627003 | U17: L | V17: 0137353541 | W17: Bandung | X17: 2013-09-28 | Y17: 3273232809130001 | Z17: Islam | AA17: Saturnus Timur I No. 4 | AB17: Kec. Rancasari | AC17: 40286 | AD17: 081809405660 | AF17: Mochamad Rangga Rhamdany | AG17: 1984 | AH17: Flaminia Occitanie Adrial | AI17: 1986 | AJ17: 7 A
A18: aiai.26kalia.m@gmail.com | B18: Aisyah Kalia Mahya | D18: =IF(E18="","",COUNTIF(B:B,E18)) -> 0 | E18: Alaric Isra Rizaki | F18: VII Thalhah bin Ubaidillah | G18: Sahri Fauzan, S.Pd. | R18: 17 | S18: ALANA AISHA FARA | T18: 2526067 | U18: P | V18: 0128979528 | W18: Bandung | X18: 2012-06-09 | Y18: 3273224906120005 | Z18: Islam | AA18: Komp. Pesona Ciwastra Permai Blok C1 No. 3 | AB18: Kec. Buahbatu | AC18: 40286 | AD18: 08562277967 | AF18: DENI HAMDANI | AG18: 1978 | AH18: AZIZAH | AI18: 1980 | AJ18: 8 C
A19: aisyahsoebekti@gmail.com | B19: Aisyah Lathifah Soebekti | D19: =IF(E19="","",COUNTIF(B:B,E19)) -> 1 | E19: Alby Raiki Elfarizi | F19: VII Abu Bakar Ash-shiddiq | G19: Lespi Nurul izzati, S.Ag. | R19: 18 | S19: ALARIC ISRA RIZAKI | T19: 2627070 | U19: L | V19: 3146870294 | W19: Bandung | X19: 2014-05-16 | Y19: 3273201605140001 | Z19: Islam | AA19: KOMP. DE MARAKESH BLOK B4 NO.16 | AB19: Kec. Rancasari | AC19: 40613 | AD19: 085318461501 | AF19: Ahmed Zaki Akbar | AG19: 1979 | AH19: Nuryanti Riani | AI19: 1980 | AJ19: 7 C
A20: ttqalfitrahsmp@gmail.com | B20: Aisyah Lathifah Soebekti | D20: =IF(E20="","",COUNTIF(B:B,E20)) -> 2 | E20: Alea Izzatunnisa Aurora | F20: VII Abu Bakar Ash-shiddiq | G20: Lespi Nurul izzati, S.Ag. | R20: 19 | S20: Alby Raiki Elfarizi | T20: 2627004 | U20: L | V20: 3135407479 | W20: Bandung | X20: 2013-11-06 | Y20: 3273220611130003 | Z20: Islam | AA20: Jl. Bahagia No. 7 | AB20: Kec. Buahbatu | AC20: 40286 | AD20: 081277773081 | AF20: Yadi Cahyadi | AG20: 1977 | AH20: Nia Purnamasari | AI20: 1981 | AJ20: 7 A
A21: alana090612@gmail.com | B21: Akma Faizia Khaerunnisa | D21: =IF(E21="","",COUNTIF(B:B,E21)) -> 1 | E21: Alea Qurota 'ayun | F21: IX Utsman bin Affan | G21: Sahri Fauzan, S.Pd. | R21: 20 | S21: Alea Izzatunnisa Aurora | T21: 2627005 | U21: P | V21: 3140779867 | W21: Bandung | X21: 2014-03-29 | Y21: 3273136903140002 | Z21: Islam | AA21: Komp. Buana Soetta Residence Blok E No. 4 | AB21: Kec. Gedebage | AD21: 083816338330 | AF21: Agus Rachmat Soleh | AG21: 1977 | AH21: Afriani Samya Nugraha | AI21: 1984 | AJ21: 7 A
A22: kmaaazs111@gmail.com | B22: Akma Faizia Khaerunnisa | D22: =IF(E22="","",COUNTIF(B:B,E22)) -> 1 | E22: Alesha Sabreen Jinca | F22: VII Thalhah bin Ubaidillah | G22: Sahri Fauzan, S.Pd. | R22: 21 | S22: Alea Qurota 'ayun | T22: 2425064 | U22: P | V22: 3119815368 | W22: BANDUNG | X22: 2011-05-04 | Y22: 3273234405110001 | Z22: Islam | AA22: Jl Babakan Wadana | AB22: Kec. Rancasari | AC22: 40292 | AD22: 081806269815 | AE22: iyam15149@gmail.com | AF22: Warmin | AG22: 1974 | AH22: MARYAM | AI22: 1971 | AJ22: 9 A
A23: uno77008@gmail.com | B23: Al Junno Arkaan Kyonando | D23: =IF(E23="","",COUNTIF(B:B,E23)) -> 1 | E23: Alifiandra Daffa Pradipta | F23: VII Abu Bakar Ash-shiddiq | G23: Agus Sayyidul Ayyam, S.Pd. | R23: 22 | S23: Alesha Sabreen Jinca | T23: 2627071 | U23: P | V23: 0143723327 | W23: Bandung | X23: 2014-01-31 | Y23: 3275067101140002 | Z23: Islam | AA23: Grand Sharon Residence Jl. Plumeria 4 No. 21 | AB23: Kec. Rancasari | AC23: 40292 | AD23: 085317800040 | AE23: senojinca@gmail.com | AF23: Antaseno Septian Jinca | AG23: 1986 | AH23: FIFIN ZURAIDAH AL ADAWIYAH | AI23: 1985 | AJ23: 7 C
A24: alana090612@gmail.com | B24: Alana Aisha Fara | D24: =IF(E24="","",COUNTIF(B:B,E24)) -> 1 | E24: Allaric Mahadika Putra Purnama | F24: VIII Abdurrahman bin Auf | G24: Lespi Nurul Izzati, S.Pd. | R24: 23 | S24: ALIFIANDRA DAFFA PRADIPTA | T24: 2627006 | U24: L | V24: 0142168304 | W24: BANDUNG | X24: 2014-01-01 | Y24: 3273230101140002 | Z24: Islam | AA24: JL. DERWATI NO.34 | AB24: Kec. Rancasari | AC24: 40296 | AD24: 081214680314 | AE24: Taniamuthakarina86@gmail.com | AF24: DICKY SETIO BUDI RAHAYU | AG24: 1982 | AH24: TANIA MUTHAKARINA | AI24: 1986 | AJ24: 7 A
A25: niapurnamasari604@gmail.com | B25: Alby Raiki Elfarizi | D25: =IF(E25="","",COUNTIF(B:B,E25)) -> 0 | E25: Allisya Rainafa | F25: IX Ja'far bin Abi Thalib | G25: Sahri Fauzan, S.Pd. | R25: 24 | S25: Allaric Mahadika Putra Purnama | T25: 2526034 | U25: L | V25: 0132962601 | W25: Bandung | X25: 2013-06-16 | Y25: 3273081606130002 | Z25: Islam | AA25: JL. Tmn Merkuri Timur No. 3 U 14 | AB25: Kec. Rancasari | AD25: 087823848989 | AF25: Purnama Alam | AG25: 1985 | AH25: Rizky Fitria Utami Widyodoro | AI25: 1986 | AJ25: 8 B
A26: aleaizzatunnisaurora@gmail.com | B26: Alea Izzatunnisa Aurora | D26: =IF(E26="","",COUNTIF(B:B,E26)) -> 2 | E26: Almira Kinar Larasati | F26: VII Ali bin Abi Thalib | G26: Sabrina Niela Ni'ami, S.Pd. | R26: 25 | S26: Allisya Rainafa | T26: 2425002 | U26: P | V26: 0123947489 | W26: Bandung | X26: 2012-01-05 | Y26: 3273234501120001 | Z26: Islam | AA26: Jl. Saturnus VIII No. 2 Margahayu Raya Bandung | AB26: Kec. Rancasari | AD26: 081394529119 | AF26: DEDI MULYADI | AG26: 1972 | AH26: LIGAR NURINTAN | AI26: 1975 | AJ26: 9 C
A27: leaa89178@gmail.com | B27: Alea Izzatunnisa Aurora | D27: =IF(E27="","",COUNTIF(B:B,E27)) -> 1 | E27: Almira nur syafiya | F27: VII Abu Bakar Ash-shiddiq | G27: Agus Sayyidul Ayyam, S.Pd. | R27: 26 | S27: Almira Kinar Larasati | T27: 2627034 | U27: P | V27: 0148402626 | W27: Banyumas | X27: 2014-11-26 | Y27: 3302226611140002 | Z27: Islam | AA27: Karangtengah | AB27: Kec. Baturaden | AD27: 082322506004 | AF27: Agung Nugroho | AG27: 1989 | AH27: Noer Indah Kumaladewi | AI27: 1989 | AJ27: 7 B
A28: aleaqurotaayun401@gmail.com | B28: Alea Qurota 'ayun | D28: =IF(E28="","",COUNTIF(B:B,E28)) -> 1 | E28: Almira Rahma | F28: VII Ali bin Abi Thalib | G28: Marwan Malik Ibrahim, S.Pd. | R28: 27 | S28: ALMIRA NUR SYAFIYA | T28: 2627007 | U28: P | V28: 0134143714 | W28: BANDUNG | X28: 2013-08-08 | Y28: 3273084808130001 | Z28: Islam | AA28: JALAN NEPTUNUS BARAT III A 29 NO 11 | AB28: Kec. Buahbatu | AC28: 40286 | AD28: 081320528289 | AF28: NARABEL FERDIANTO | AG28: 1987 | AH28: NURWITA WIDYA UTAMI | AI28: 1988 | AJ28: 7 A
A29: aleshasabreen@gmail.com | B29: Alesha Sabreen Jinca | D29: =IF(E29="","",COUNTIF(B:B,E29)) -> 3 | E29: Alya Yustisia Putri Rajamai | F29: VIII Umar bin Khattab | G29: Annida Nurrohmah | R29: 28 | S29: Almira Rahma | T29: 2627035 | U29: P | V29: 0136439945 | W29: Bandung | X29: 2013-09-27 | Y29: 3578066709130003 | Z29: Islam | AA29: Jl. Marga Asri Raya Np.23 Komp. Marga Asri | AB29: Kec. Buahbatu | AD29: 082116698456 | AF29: Rahadian Lingga Pratama | AG29: 1986 | AH29: PUTRI EKA RIZKI SUDARSONO, ST | AI29: 1987 | AJ29: 7 B
A30: ifahdwi04@gmail.com | B30: Alifah Dwi Purwani Widodo | D30: =IF(E30="","",COUNTIF(B:B,E30)) -> 1 | E30: Amanda Meisya Devina Putri | F30: IX Zubair bin Awwam | G30: Sahri Fauzan, S.Pd. | R30: 29 | S30: ALYA YUSTISIA PUTRI RAJAMAI | T30: 2526002 | U30: P | V30: 0123921614 | W30: CIANJUR | X30: 2012-11-19 | Y30: 3203015911120005 | Z30: Islam | AA30: Jl. Pembangunan | AB30: Kec. Tarogong Kidul | AC30: 44151 | AD30: 08179129395 | AF30: ENDRATNO RAJAMAI | AG30: 1976 | AH30: SUSI FATIMAH | AI30: 1976 | AJ30: 8 A
A31: alifiandradaffa01@gmail.com | B31: Alifiandra Daffa Pradipta | D31: =IF(E31="","",COUNTIF(B:B,E31)) -> 2 | E31: Amarra Zulaikha Sakhee | F31: VIII Umar bin Khattab | G31: Muhammad Nurrachman Satrio, S.Pd. | R31: 30 | S31: AMANDA MEISYA DEVINA PUTRI | T31: 2425003 | U31: P | V31: 3114654669 | W31: BANDUNG | X31: 2011-05-25 | Y31: 3273236505110001 | Z31: Islam | AA31: Jl. Saluyu Indah XIX No. 195 | AB31: Kec. Rancasari | AF31: Ade Nana | AG31: 1988 | AH31: NOVI YULIANTI | AI31: 1988 | AJ31: 9 B
A32: alaricmahadika8@gmail.com | B32: Allaric Mahadika Putra Purnama | D32: =IF(E32="","",COUNTIF(B:B,E32)) -> 1 | E32: Amira Ditia Putri Pradani | F32: VIII Abdurrahman bin Auf | G32: Lespi Nurul Izzati, S.Pd. | R32: 31 | S32: Amarra Zulaikha Sakhee | T32: 2526003 | U32: P | V32: 0125167789 | W32: Bandung | X32: 2012-09-05 | Y32: 3273234509120001 | Z32: Islam | AA32: Jl. Mars Barat No. IX No. 9 | AB32: Kec. Rancasari | AD32: 08112200033 | AF32: Ronny Wilman | AG32: 1983 | AH32: Pratiwi Prima Lestari | AI32: 1988 | AJ32: 8 A
A33: almayrakafkamaulani@gmail.com | B33: Almayra Kafka Maulani | D33: =IF(E33="","",COUNTIF(B:B,E33)) -> 2 | E33: Andari Ratu Balqis | F33: VIII Sa'ad Bin Abi Waqqash | G33: Annida Nurrohmah | R33: 32 | S33: Amira Ditia Putri Pradani | T33: 2526035 | U33: P | V33: 3127124828 | W33: Bandung | X33: 2012-11-13 | Y33: 3273225311120002 | Z33: Islam | AA33: Kamarasan Residence C1/1 Buahbatu Bojong Soang Bandung | AB33: Kec. Bojongsoang | AD33: 08157909254 | AF33: Budhi Haryanto | AG33: 1975 | AH33: SETIAWATI,S.SOS | AI33: 1976 | AJ33: 8 B
A34: agung.nug02@gmail.com | B34: Almira Kinar Larasati | D34: =IF(E34="","",COUNTIF(B:B,E34)) -> 0 | E34: Andhika Bramantya Adjie | F34: VIII Abdurrahman bin Auf | G34: Annida Nurrohmah | R34: 33 | S34: Andari Ratu Balqis | T34: 2526068 | U34: P | V34: 0125757838 | W34: Bandung | X34: 2012-11-01 | Y34: 3273234111120002 | Z34: Islam | AA34: Jl. Oliana No. 40 Grand Sharon Residen | AB34: Kec. Rancasari | AC34: 40292 | AD34: 082119631057 | AF34: Erdiansyah Pratama | AG34: 1987 | AH34: Pipit Septiani | AI34: 1987 | AJ34: 8 C
A35: kumaladewinoerindah@gmail.com | B35: Almira Kinar Larasati | D35: =IF(E35="","",COUNTIF(B:B,E35)) -> 2 | E35: Andraka Muhammad Navary | F35: IX Ja'far bin Abi Thalib | G35: Annida Nurrohmah | R35: 34 | S35: ANDHIKA BRAMANTYA ADJIE | T35: 2526036 | U35: L | V35: 0125866341 | W35: BANDUNG | X35: 2012-04-04 | Y35: 3273220404120003 | Z35: Islam | AA35: JL.SATURNUS SELATAN VIII N0.18 | AB35: Kec. Buahbatu | AC35: 40286 | AD35: 081321147570 | AF35: DIMAS PRAMUDITO | AG35: 1980 | AH35: Merina Indriastuti | AI35: 1980 | AJ35: 8 B
A36: almirasyafiya88@gmail.com | B36: Almira nur syafiya | D36: =IF(E36="","",COUNTIF(B:B,E36)) -> 3 | E36: Anggytha Rayhana Putri | F36: VIII Abdurrahman bin Auf | G36: Annida Nurrohmah | R36: 35 | S36: Andraka Muhammad Navary | T36: 2425065 | U36: L | V36: 3122628187 | W36: Bandung | X36: 2012-02-18 | Y36: 3204331802120003 | Z36: Islam | AA36: Komp De Green Grande Blok C-24 | AB36: Kec. Buahbatu | AC36: 40286 | AD36: 08157283058 | AE36: rbroerys@gmail.com | AF36: Ryan Broery Sonitri | AG36: 1983 | AH36: EVA AGUSTINA , SE | AI36: 1983 | AJ36: 9 C
A37: putriekarizki@gmail.com | B37: Almira Rahma | D37: =IF(E37="","",COUNTIF(B:B,E37)) -> 1 | E37: Annasya Hana Fadillah | F37: IX Ja'far bin Abi Thalib | G37: Sahri Fauzan, S.Pd. | R37: 36 | S37: Anggytha Rayhana Putri | T37: 2526037 | U37: P | V37: 0122337417 | W37: Garut | X37: 2012-11-21 | Y37: 3273236111120001 | Z37: Islam | AA37: Komp. Griya Saluyu Blok AA 54 | AB37: Kec. Rancasari | AC37: 40613 | AD37: 082130003919 | AF37: Bobby | AG37: 1985 | AH37: Supriatin | AI37: 1985 | AJ37: 8 B
A38: alhome1912@gmail.com | B38: Alya Yustisia Putri Rajamai | D38: =IF(E38="","",COUNTIF(B:B,E38)) -> 1 | E38: Aqeela Aruna Shanum | F38: VIII Umar bin Khattab | G38: Muhammad Nurrachman Satrio, S.Pd. | R38: 37 | S38: Annasya Hana Fadillah | T38: 2425033 | U38: P | V38: 0116795429 | W38: Bandung | X38: 2011-08-17 | Y38: 3273225708110002 | Z38: Islam | AA38: JL. NEPTUNUS BARAT BLOK A 10 NO. 4 MARGAHAYU RAYA BARAT SEKEJATI BANDUNG | AB38: Kec. Buahbatu | AD38: 089655136953 | AF38: ARIE YULIANSYAH | AG38: 1979 | AH38: SRI MULYASTUTI | AI38: 1982 | AJ38: 9 C
A39: annidanr63@gmail.com | B39: Alya Yustisia Putri Rajamai | D39: =IF(E39="","",COUNTIF(B:B,E39)) -> 0 | E39: Aqiel Harith Adhyastha | F39: VIII Abdurrahman bin Auf | G39: Annida Nurrohmah | R39: 38 | S39: Aqeela Aruna Shanum | T39: 2526004 | U39: P | V39: 3133625687 | W39: Bandung | X39: 2013-04-05 | Y39: 3273234504130001 | Z39: Islam | AA39: JL. Saturnus tengah II No.17 | AB39: Kec. Rancasari | AC39: 40286 | AD39: 081322500088 | AF39: Yayat Supriatna | AG39: 1964 | AH39: Yozie Verra Imelda | AI39: 1977 | AJ39: 8 A
A40: bluerberyy@gmail.com | B40: Alya Yustisia Putri Rajamai | D40: =IF(E40="","",COUNTIF(B:B,E40)) -> 1 | E40: Aqila Shazia Sofyan | F40: VIII Sa'ad Bin Abi Waqqash | G40: Annida Nurrohmah | R40: 39 | S40: AQIEL HARITH ADHYASTHA | T40: 2526038 | U40: L | V40: 3133917955 | W40: Bandung | X40: 2013-05-30 | Y40: 3204283005130001 | Z40: Islam | AA40: Jingga Residence B-14 | AB40: Kec. Rancasari | AD40: 08122303595 | AF40: AJAR DWI HERNOWO | AG40: 1976 | AH40: YASHOUMI SETIATIN | AI40: 1978 | AJ40: 8 B
...

Sheet student-parent-class-teacher
A1: email | B1: username | C1: nis | D1: student_name | E1: class | F1: teacher | G1: parent_name | H1: email_parent
A2: nengdara.hdr@gmail.com | B2: abdulpradipta | C2: 0141066499 | D2: Abdul Rayhan Pradipta | E2: VII Thalhah bin Ubaidillah | F2: Marwan Malik Ibrahim, S.Pd. | G2: Dara Indah Pertiwi
A3: abhinayasyafiq19@gmail.com | B3: abhinayanatadikara | C3: 3149021359 | D3: Abhinaya Syafiq Natadikara | E3: VII Abu Bakar Ash-shiddiq | F3: Agus Sayyidul Ayyam, S.Pd. | G3: Ratna Widyaningsih | H3: rawidya80@gmail.com
A4: abyazfauzil@gmail.com | B4: abyazfirjatullah | C4: 3126431912 | D4: Abyaz Fauzil Firjatullah | E4: VIII Umar bin Khattab | F4: Sabrina Niela Ni'ami, S.Pd. | G4: Yeye Fahrina Inayatillah
A5: adam.avicii.adelard@gmail.com | B5: adamadelard | C5: 0138107714 | D5: Adam Avicii Adelard | E5: VII Thalhah bin Ubaidillah | F5: Sahri Fauzan, S.Pd. | G5: Ratna Hartati
A6: azzahra11022014@gmail.com | B6: adindazahra | C6: 3143690788 | D6: Adinda Fatimah Zahra | E6: VII Ali bin Abi Thalib | F6: Sabrina Niela Ni'ami, S.Pd. | G6: Astrisia Fitriani | H6: astrisia240883@gmail.com
A7: g3nt42007@gmail.com | B7: adreenashabira | C7: 3147257623 | D7: Adreena Shabira | E7: VII Abu Bakar Ash-shiddiq | F7: Lespi Nurul izzati, S.Ag. | G7: Kusmadini Suharti
A8: arisrinaldi79@gmail.com | B8: adzikrarinaldi | C8: 0133723976 | D8: Adzikra Athari Rinaldi | E8: VII Thalhah bin Ubaidillah | F8: Sahri Fauzan, S.Pd. | G8: Nia Sintawaty | H8: niasintawati81@gmail.com
A9: rikaandrianiyogianto@gmail.com | B9: adziqaqisya | C9: 0138471291 | D9: Adziqa naufal qisya | E9: VII Thalhah bin Ubaidillah | F9: Agus Sayyidul Ayyam, S.Pd. | G9: Rika Andriani | H9: rikaandrianiyogianto@gmail.com
A10: afifa.muktisa@gmail.com | B10: afifamuktisa | C10: 0128498183 | D10: Afifa Syakira Muktisa | E10: VIII Sa'ad Bin Abi Waqqash | F10: Bunga Sarah Istiqomah, S.Ag. | G10: Annisa Hartani
A11: afifah.naura2012@gmail.com | B11: afifahzafarani | C11: 0126787257 | D11: afifah naura Zafarani | E11: IX Utsman bin Affan | F11: Marwan Malik Ibrahim, S.Pd. | G11: Siska Maharani
B12: afnankautsar | C12: 0121695890 | D12: Afnan Maqil Kautsar | E12: IX Utsman bin Affan | F12: Bunga Sarah Istiqomah, S.Ag. | G12: Meggie Chairina
A13: agtamalika@gmail.com | B13: agtalapuri | C13: 3137745114 | D13: Agta Malika Lapuri | E13: VIII Abdurrahman bin Auf | F13: Agus Sayyidul Ayyam, S.Pd. | G13: Sheila Puspita Wulandari
B14: ahmadalfatih | C14: 3133234422 | D14: Ahmad Satria Alfatih | E14: VII Thalhah bin Ubaidillah | F14: Agus Sayyidul Ayyam, S.Pd. | G14: Hanifah Sani Spt
A15: aisyahputrisenna@gmail.com | B15: aisyahsenna | C15: 3136158343 | D15: Aisyah Hayundya Putri Senna | E15: VIII Sa'ad Bin Abi Waqqash | F15: Bunga Sarah Istiqomah, S.Ag. | G15: Hayunieta | H15: hayunieta@gmail.com
A16: alana090612@gmail.com | B16: akmakhaerunnisa | C16: 0124314004 | D16: Akma Faizia Khaerunnisa | E16: IX Utsman bin Affan | F16: Bunga Sarah Istiqomah, S.Ag. | G16: Suventi Turiatin | H16: ventizia2012@gmail.com
A17: uno77008@gmail.com | B17: alkyonando | C17: 0137353541 | D17: Al Junno Arkaan Kyonando | E17: VII Abu Bakar Ash-shiddiq | F17: Arai kurnia Ramadhan | G17: Flaminia Occitanie Adrial
A18: alana090612@gmail.com | B18: alanafara | C18: 0128979528 | D18: Alana Aisha Fara | E18: VIII Sa'ad Bin Abi Waqqash | F18: Arai kurnia Ramadhan | G18: Azizah
B19: alaricrizaki | C19: 3146870294 | D19: Alaric Isra Rizaki | E19: VII Thalhah bin Ubaidillah | F19: Sahri Fauzan, S.Pd. | G19: Nuryanti Riani
A20: niapurnamasari604@gmail.com | B20: albyelfarizi | C20: 3135407479 | D20: Alby Raiki Elfarizi | E20: VII Abu Bakar Ash-shiddiq | F20: Lespi Nurul izzati, S.Ag. | G20: Nia Purnamasari
A21: aleaizzatunnisaurora@gmail.com | B21: aleaaurora | C21: 3140779867 | D21: Alea Izzatunnisa Aurora | E21: VII Abu Bakar Ash-shiddiq | F21: Lespi Nurul izzati, S.Ag. | G21: Afriani Samya Nugraha
A22: aleaqurotaayun401@gmail.com | B22: aleaayun | C22: 3119815368 | D22: Alea Qurota 'ayun | E22: IX Utsman bin Affan | F22: Sahri Fauzan, S.Pd. | G22: Maryam | H22: iyam15149@gmail.com
A23: aleshasabreen@gmail.com | B23: aleshajinca | C23: 0143723327 | D23: Alesha Sabreen Jinca | E23: VII Thalhah bin Ubaidillah | F23: Sahri Fauzan, S.Pd. | G23: Fifin Zuraidah Al Adawiyah | H23: senojinca@gmail.com
A24: alifiandradaffa01@gmail.com | B24: alifiandrapradipta | C24: 0142168304 | D24: Alifiandra Daffa Pradipta | E24: VII Abu Bakar Ash-shiddiq | F24: Agus Sayyidul Ayyam, S.Pd. | G24: Tania Muthakarina | H24: taniamuthakarina86@gmail.com
A25: alaricmahadika8@gmail.com | B25: allaricpurnama | C25: 0132962601 | D25: Allaric Mahadika Putra Purnama | E25: VIII Abdurrahman bin Auf | F25: Lespi Nurul izzati, S.Ag. | G25: Rizky Fitria Utami Widyodoro
B26: allisyarainafa | C26: 0123947489 | D26: Allisya Rainafa | E26: IX Ja'far bin Abi Thalib | F26: Sahri Fauzan, S.Pd. | G26: Ligar Nurintan
A27: agung.nug02@gmail.com | B27: almiralarasati | C27: 0148402626 | D27: Almira Kinar Larasati | E27: VII Ali bin Abi Thalib | F27: Sabrina Niela Ni'ami, S.Pd. | G27: Noer Indah Kumaladewi
A28: almirasyafiya88@gmail.com | B28: almirasyafiya | C28: 0134143714 | D28: Almira nur syafiya | E28: VII Abu Bakar Ash-shiddiq | F28: Agus Sayyidul Ayyam, S.Pd. | G28: Nurwita Widya Utami
A29: putriekarizki@gmail.com | B29: almirarahma | C29: 0136439945 | D29: Almira Rahma | E29: VII Ali bin Abi Thalib | F29: Marwan Malik Ibrahim, S.Pd. | G29: Putri Eka Rizki Sudarsono, St
A30: alhome1912@gmail.com | B30: alyarajamai | C30: 0123921614 | D30: Alya Yustisia Putri Rajamai | E30: VIII Umar bin Khattab | F30: Annida Nurrohmah | G30: Susi Fatimah
A31: devinameisya25@gmail.com | B31: amandaputri | C31: 3114654669 | D31: Amanda Meisya Devina Putri | E31: IX Zubair bin Awwam | F31: Sahri Fauzan, S.Pd. | G31: Novi Yulianti
A32: amarrazs5912@gmail.com | B32: amarrasakhee | C32: 0125167789 | D32: Amarra Zulaikha Sakhee | E32: VIII Umar bin Khattab | F32: Muhammad Nurrachman Satrio, S.Pd. | G32: Pratiwi Prima Lestari
A33: amira.dpp.13@gmail.com | B33: amirapradani | C33: 3127124828 | D33: Amira Ditia Putri Pradani | E33: VIII Abdurrahman bin Auf | F33: Lespi Nurul izzati, S.Ag. | G33: Setiawati,S.Sos
A34: pit566774@gmail.com | B34: andaribalqis | C34: 0125757838 | D34: Andari Ratu Balqis | E34: VIII Sa'ad Bin Abi Waqqash | F34: Annida Nurrohmah | G34: Pipit Septiani
B35: andhikaadjie | C35: 0125866341 | D35: Andhika Bramantya Adjie | E35: VIII Abdurrahman bin Auf | F35: Annida Nurrohmah | G35: Merina Indriastuti
A36: andrakanavary@gmail.com | B36: andrakanavary | C36: 3122628187 | D36: Andraka Muhammad Navary | E36: IX Ja'far bin Abi Thalib | F36: Annida Nurrohmah | G36: Eva Agustina , Se | H36: rbroerys@gmail.com
A37: anggytharayhana2012@gmail.com | B37: anggythaputri | C37: 0122337417 | D37: Anggytha Rayhana Putri | E37: VIII Abdurrahman bin Auf | F37: Annida Nurrohmah | G37: Supriatin
A38: pit566774@gmail.com | B38: annasyafadillah | C38: 0116795429 | D38: Annasya Hana Fadillah | E38: IX Ja'far bin Abi Thalib | F38: Sahri Fauzan, S.Pd. | G38: Sri Mulyastuti
A39: aqeelaaruna54@gmail.com | B39: aqeelashanum | C39: 3133625687 | D39: Aqeela Aruna Shanum | E39: VIII Umar bin Khattab | F39: Muhammad Nurrachman Satrio, S.Pd. | G39: Yozie Verra Imelda
B40: aqieladhyastha | C40: 3133917955 | D40: Aqiel Harith Adhyastha | E40: VIII Abdurrahman bin Auf | F40: Annida Nurrohmah | G40: Yashoumi Setiatin
...

Sheet student
A1: email | B1: nis | C1: fullname | D1: username | E1: password | F1: gender | G1: birth_place | H1: birth_date
A2: nengdara.hdr@gmail.com | B2: =VLOOKUP(C2,raw!S:AA,4,0) -> 0141066499 | C2: Abdul Rayhan Pradipta | D2: abdulpradipta | E2: =_xlfn.CONCAT(D2,"2026") -> abdulpradipta2026 | F2: Ikhwan | G2: Payakumbuh | H2: 2014-04-15
A3: abhinayasyafiq19@gmail.com | B3: =VLOOKUP(C3,raw!S:AA,4,0) -> 3149021359 | C3: Abhinaya Syafiq Natadikara | D3: abhinayanatadikara | E3: =_xlfn.CONCAT(D3,"2026") -> abhinayanatadikara2026 | F3: Ikhwan | G3: Tangerang | H3: 2014-03-19
A4: abyazfauzil@gmail.com | B4: =VLOOKUP(C4,raw!S:AA,4,0) -> 3126431912 | C4: Abyaz Fauzil Firjatullah | D4: abyazfirjatullah | E4: =_xlfn.CONCAT(D4,"2026") -> abyazfirjatullah2026 | F4: Ikhwan | G4: Bandung | H4: 2012-05-28
A5: adam.avicii.adelard@gmail.com | B5: =VLOOKUP(C5,raw!S:AA,4,0) -> 0138107714 | C5: Adam Avicii Adelard | D5: adamadelard | E5: =_xlfn.CONCAT(D5,"2026") -> adamadelard2026 | F5: Ikhwan | G5: Bandung | H5: 2013-11-13
A6: azzahra11022014@gmail.com | B6: =VLOOKUP(C6,raw!S:AA,4,0) -> 3143690788 | C6: Adinda Fatimah Zahra | D6: adindazahra | E6: =_xlfn.CONCAT(D6,"2026") -> adindazahra2026 | F6: Akhwat | G6: Semarang | H6: 2014-02-11
A7: g3nt42007@gmail.com | B7: =VLOOKUP(C7,raw!S:AA,4,0) -> 3147257623 | C7: Adreena Shabira | D7: adreenashabira | E7: =_xlfn.CONCAT(D7,"2026") -> adreenashabira2026 | F7: Akhwat | G7: Bandung | H7: 2014-05-26
A8: arisrinaldi79@gmail.com | B8: =VLOOKUP(C8,raw!S:AA,4,0) -> 0133723976 | C8: Adzikra Athari Rinaldi | D8: adzikrarinaldi | E8: =_xlfn.CONCAT(D8,"2026") -> adzikrarinaldi2026 | F8: Akhwat | G8: Bandung | H8: 2013-12-07
A9: rikaandrianiyogianto@gmail.com | B9: =VLOOKUP(C9,raw!S:AA,4,0) -> 0138471291 | C9: Adziqa Naufal Qisya | D9: adziqaqisya | E9: =_xlfn.CONCAT(D9,"2026") -> adziqaqisya2026 | F9: Ikhwan | G9: Cimahi | H9: 2013-09-28
A10: afifa.muktisa@gmail.com | B10: =VLOOKUP(C10,raw!S:AA,4,0) -> 0128498183 | C10: Afifa Syakira Muktisa | D10: afifamuktisa | E10: =_xlfn.CONCAT(D10,"2026") -> afifamuktisa2026 | F10: Akhwat | G10: Bandung | H10: 2012-03-27
A11: afifah.naura2012@gmail.com | B11: =VLOOKUP(C11,raw!S:AA,4,0) -> 0126787257 | C11: Afifah Naura Zafarani | D11: afifahzafarani | E11: =_xlfn.CONCAT(D11,"2026") -> afifahzafarani2026 | F11: Akhwat | G11: Blitar | H11: 2012-04-08
B12: =VLOOKUP(C12,raw!S:AA,4,0) -> 0121695890 | C12: Afnan Maqil Kautsar | D12: afnankautsar | E12: =_xlfn.CONCAT(D12,"2026") -> afnankautsar2026 | F12: Ikhwan | G12: Bandung | H12: 2012-07-01
A13: agtamalika@gmail.com | B13: =VLOOKUP(C13,raw!S:AA,4,0) -> 3137745114 | C13: Agta Malika Lapuri | D13: agtalapuri | E13: =_xlfn.CONCAT(D13,"2026") -> agtalapuri2026 | F13: Akhwat | G13: Bandung | H13: 2013-03-08
B14: =VLOOKUP(C14,raw!S:AA,4,0) -> 3133234422 | C14: Ahmad Satria Alfatih | D14: ahmadalfatih | E14: =_xlfn.CONCAT(D14,"2026") -> ahmadalfatih2026 | F14: Ikhwan | G14: Balikpapan | H14: 2013-09-14
A15: aisyahputrisenna@gmail.com | B15: =VLOOKUP(C15,raw!S:AA,4,0) -> 3136158343 | C15: Aisyah Hayundya Putri Senna | D15: aisyahsenna | E15: =_xlfn.CONCAT(D15,"2026") -> aisyahsenna2026 | F15: Akhwat | G15: Pontianak | H15: 2013-01-31
A16: alana090612@gmail.com | B16: =VLOOKUP(C16,raw!S:AA,4,0) -> 0124314004 | C16: Akma Faizia Khaerunnisa | D16: akmakhaerunnisa | E16: =_xlfn.CONCAT(D16,"2026") -> akmakhaerunnisa2026 | F16: Akhwat | G16: Bandung | H16: 2012-07-17
A17: uno77008@gmail.com | B17: =VLOOKUP(C17,raw!S:AA,4,0) -> 0137353541 | C17: Al Junno Arkaan Kyonando | D17: alkyonando | E17: =_xlfn.CONCAT(D17,"2026") -> alkyonando2026 | F17: Ikhwan | G17: Bandung | H17: 2013-09-28
A18: alana090612@gmail.com | B18: =VLOOKUP(C18,raw!S:AA,4,0) -> 0128979528 | C18: Alana Aisha Fara | D18: alanafara | E18: =_xlfn.CONCAT(D18,"2026") -> alanafara2026 | F18: Akhwat | G18: Bandung | H18: 2012-06-09
B19: =VLOOKUP(C19,raw!S:AA,4,0) -> 3146870294 | C19: Alaric Isra Rizaki | D19: alaricrizaki | E19: =_xlfn.CONCAT(D19,"2026") -> alaricrizaki2026 | F19: Ikhwan | G19: Bandung | H19: 2014-05-16
A20: niapurnamasari604@gmail.com | B20: =VLOOKUP(C20,raw!S:AA,4,0) -> 3135407479 | C20: Alby Raiki Elfarizi | D20: albyelfarizi | E20: =_xlfn.CONCAT(D20,"2026") -> albyelfarizi2026 | F20: Ikhwan | G20: Bandung | H20: 2013-11-06
A21: aleaizzatunnisaurora@gmail.com | B21: =VLOOKUP(C21,raw!S:AA,4,0) -> 3140779867 | C21: Alea Izzatunnisa Aurora | D21: aleaaurora | E21: =_xlfn.CONCAT(D21,"2026") -> aleaaurora2026 | F21: Akhwat | G21: Bandung | H21: 2014-03-29
A22: aleaqurotaayun401@gmail.com | B22: =VLOOKUP(C22,raw!S:AA,4,0) -> 3119815368 | C22: Alea Qurota 'Ayun | D22: aleaayun | E22: =_xlfn.CONCAT(D22,"2026") -> aleaayun2026 | F22: Akhwat | G22: Bandung | H22: 2011-05-04
A23: aleshasabreen@gmail.com | B23: =VLOOKUP(C23,raw!S:AA,4,0) -> 0143723327 | C23: Alesha Sabreen Jinca | D23: aleshajinca | E23: =_xlfn.CONCAT(D23,"2026") -> aleshajinca2026 | F23: Akhwat | G23: Bandung | H23: 2014-01-31
A24: alifiandradaffa01@gmail.com | B24: =VLOOKUP(C24,raw!S:AA,4,0) -> 0142168304 | C24: Alifiandra Daffa Pradipta | D24: alifiandrapradipta | E24: =_xlfn.CONCAT(D24,"2026") -> alifiandrapradipta2026 | F24: Ikhwan | G24: Bandung | H24: 2014-01-01
A25: alaricmahadika8@gmail.com | B25: =VLOOKUP(C25,raw!S:AA,4,0) -> 0132962601 | C25: Allaric Mahadika Putra Purnama | D25: allaricpurnama | E25: =_xlfn.CONCAT(D25,"2026") -> allaricpurnama2026 | F25: Ikhwan | G25: Bandung | H25: 2013-06-16
B26: =VLOOKUP(C26,raw!S:AA,4,0) -> 0123947489 | C26: Allisya Rainafa | D26: allisyarainafa | E26: =_xlfn.CONCAT(D26,"2026") -> allisyarainafa2026 | F26: Akhwat | G26: Bandung | H26: 2012-01-05
A27: agung.nug02@gmail.com | B27: =VLOOKUP(C27,raw!S:AA,4,0) -> 0148402626 | C27: Almira Kinar Larasati | D27: almiralarasati | E27: =_xlfn.CONCAT(D27,"2026") -> almiralarasati2026 | F27: Akhwat | G27: Banyumas | H27: 2014-11-26
A28: almirasyafiya88@gmail.com | B28: =VLOOKUP(C28,raw!S:AA,4,0) -> 0134143714 | C28: Almira Nur Syafiya | D28: almirasyafiya | E28: =_xlfn.CONCAT(D28,"2026") -> almirasyafiya2026 | F28: Akhwat | G28: Bandung | H28: 2013-08-08
A29: putriekarizki@gmail.com | B29: =VLOOKUP(C29,raw!S:AA,4,0) -> 0136439945 | C29: Almira Rahma | D29: almirarahma | E29: =_xlfn.CONCAT(D29,"2026") -> almirarahma2026 | F29: Akhwat | G29: Bandung | H29: 2013-09-27
A30: alhome1912@gmail.com | B30: =VLOOKUP(C30,raw!S:AA,4,0) -> 0123921614 | C30: Alya Yustisia Putri Rajamai | D30: alyarajamai | E30: =_xlfn.CONCAT(D30,"2026") -> alyarajamai2026 | F30: Akhwat | G30: Cianjur | H30: 2012-11-19
A31: devinameisya25@gmail.com | B31: =VLOOKUP(C31,raw!S:AA,4,0) -> 3114654669 | C31: Amanda Meisya Devina Putri | D31: amandaputri | E31: =_xlfn.CONCAT(D31,"2026") -> amandaputri2026 | F31: Akhwat | G31: Bandung | H31: 2011-05-25
A32: amarrazs5912@gmail.com | B32: =VLOOKUP(C32,raw!S:AA,4,0) -> 0125167789 | C32: Amarra Zulaikha Sakhee | D32: amarrasakhee | E32: =_xlfn.CONCAT(D32,"2026") -> amarrasakhee2026 | F32: Akhwat | G32: Bandung | H32: 2012-09-05
A33: amira.dpp.13@gmail.com | B33: =VLOOKUP(C33,raw!S:AA,4,0) -> 3127124828 | C33: Amira Ditia Putri Pradani | D33: amirapradani | E33: =_xlfn.CONCAT(D33,"2026") -> amirapradani2026 | F33: Akhwat | G33: Bandung | H33: 2012-11-13
A34: pit566774@gmail.com | B34: =VLOOKUP(C34,raw!S:AA,4,0) -> 0125757838 | C34: Andari Ratu Balqis | D34: andaribalqis | E34: =_xlfn.CONCAT(D34,"2026") -> andaribalqis2026 | F34: Akhwat | G34: Bandung | H34: 2012-11-01
B35: =VLOOKUP(C35,raw!S:AA,4,0) -> 0125866341 | C35: Andhika Bramantya Adjie | D35: andhikaadjie | E35: =_xlfn.CONCAT(D35,"2026") -> andhikaadjie2026 | F35: Ikhwan | G35: Bandung | H35: 2012-04-04
A36: andrakanavary@gmail.com | B36: =VLOOKUP(C36,raw!S:AA,4,0) -> 3122628187 | C36: Andraka Muhammad Navary | D36: andrakanavary | E36: =_xlfn.CONCAT(D36,"2026") -> andrakanavary2026 | F36: Ikhwan | G36: Bandung | H36: 2012-02-18
A37: anggytharayhana2012@gmail.com | B37: =VLOOKUP(C37,raw!S:AA,4,0) -> 0122337417 | C37: Anggytha Rayhana Putri | D37: anggythaputri | E37: =_xlfn.CONCAT(D37,"2026") -> anggythaputri2026 | F37: Akhwat | G37: Garut | H37: 2012-11-21
A38: pit566774@gmail.com | B38: =VLOOKUP(C38,raw!S:AA,4,0) -> 0116795429 | C38: Annasya Hana Fadillah | D38: annasyafadillah | E38: =_xlfn.CONCAT(D38,"2026") -> annasyafadillah2026 | F38: Akhwat | G38: Bandung | H38: 2011-08-17
A39: aqeelaaruna54@gmail.com | B39: =VLOOKUP(C39,raw!S:AA,4,0) -> 3133625687 | C39: Aqeela Aruna Shanum | D39: aqeelashanum | E39: =_xlfn.CONCAT(D39,"2026") -> aqeelashanum2026 | F39: Akhwat | G39: Bandung | H39: 2013-04-05
B40: =VLOOKUP(C40,raw!S:AA,4,0) -> 3133917955 | C40: Aqiel Harith Adhyastha | D40: aqieladhyastha | E40: =_xlfn.CONCAT(D40,"2026") -> aqieladhyastha2026 | F40: Ikhwan | G40: Bandung | H40: 2013-05-30
...

Sheet parent
A1: parent_name | B1: gender | C1: email_parent
A2: Dara Indah Pertiwi | B2: Akhwat
A3: Ratna Widyaningsih | B3: Akhwat | C3: rawidya80@gmail.com
A4: Yeye Fahrina Inayatillah | B4: Akhwat
A5: Ratna Hartati | B5: Akhwat
A6: Astrisia Fitriani | B6: Akhwat | C6: astrisia240883@gmail.com
A7: Kusmadini Suharti | B7: Akhwat
A8: Nia Sintawaty | B8: Akhwat | C8: niasintawati81@gmail.com
A9: Rika Andriani | B9: Akhwat | C9: rikaandrianiyogianto@gmail.com
A10: Annisa Hartani | B10: Akhwat
A11: Siska Maharani | B11: Akhwat
A12: Meggie Chairina | B12: Akhwat
A13: Sheila Puspita Wulandari | B13: Akhwat
A14: Hanifah Sani Spt | B14: Akhwat
A15: Hayunieta | B15: Akhwat | C15: hayunieta@gmail.com
A16: Suventi Turiatin | B16: Akhwat | C16: ventizia2012@gmail.com
A17: Flaminia Occitanie Adrial | B17: Akhwat
A18: Azizah | B18: Akhwat
A19: Nuryanti Riani | B19: Akhwat
A20: Nia Purnamasari | B20: Akhwat
A21: Afriani Samya Nugraha | B21: Akhwat
A22: Maryam | B22: Akhwat | C22: iyam15149@gmail.com
A23: Fifin Zuraidah Al Adawiyah | B23: Akhwat | C23: senojinca@gmail.com
A24: Tania Muthakarina | B24: Akhwat | C24: taniamuthakarina86@gmail.com
A25: Rizky Fitria Utami Widyodoro | B25: Akhwat
A26: Ligar Nurintan | B26: Akhwat
A27: Noer Indah Kumaladewi | B27: Akhwat
A28: Nurwita Widya Utami | B28: Akhwat
A29: Putri Eka Rizki Sudarsono, St | B29: Akhwat
A30: Susi Fatimah | B30: Akhwat
A31: Novi Yulianti | B31: Akhwat
A32: Pratiwi Prima Lestari | B32: Akhwat
A33: Setiawati,S.Sos | B33: Akhwat
A34: Pipit Septiani | B34: Akhwat
A35: Merina Indriastuti | B35: Akhwat
A36: Eva Agustina , Se | B36: Akhwat | C36: rbroerys@gmail.com
A37: Supriatin | B37: Akhwat
A38: Sri Mulyastuti | B38: Akhwat
A39: Yozie Verra Imelda | B39: Akhwat
A40: Yashoumi Setiatin | B40: Akhwat
...

Sheet teacher
A1: kode | B1: teacher
A2: ASA | B2: Agus Sayyidul Ayyam, S.Pd.
A3: ANN | B3: Annida Nurrohmah
A4: AKR | B4: Arai kurnia Ramadhan
A5: BSI | B5: Bunga Sarah Istiqomah, S.Ag.
A6: LNI | B6: Lespi Nurul izzati, S.Ag.
A7: MMI | B7: Marwan Malik Ibrahim, S.Pd.
A8: MNS | B8: Muhammad Nurrachman Satrio, S.Pd.
A9: SNN | B9: Sabrina Niela Ni'ami, S.Pd.
A10: SHF | B10: Sahri Fauzan, S.Pd.

Sheet class
A1: class
A2: VII Thalhah bin Ubaidillah
A3: VII Abu Bakar Ash-shiddiq
A4: VIII Umar bin Khattab
A5: VII Ali bin Abi Thalib
A6: VIII Sa'ad Bin Abi Waqqash
A7: IX Utsman bin Affan
A8: VIII Abdurrahman bin Auf
A9: IX Ja'far bin Abi Thalib
A10: IX Zubair bin Awwam

Sheet surah
A1: No | B1: Surat | C1: Juz
A2: 1 | B2: Al Fatihah | C2: 1
A3: 2 | B3: Al Baqarah | C3: 1
A4: 3 | B4: Al Imran
A5: 4 | B5: An Nisa
A6: 5 | B6: Al Maidah
A7: 6 | B7: Al An'Am
A8: 7 | B8: Al 'Araf
A9: 8 | B9: Al Anfal
A10: 9 | B10: At Taubah
A11: 10 | B11: Yunus
A12: 11 | B12: Hud
A13: 12 | B13: Yusuf
A14: 13 | B14: Ar - Raad
A15: 14 | B15: Ibrahim
... A62: 61 | B62: As Shaff
A63: 62 | B63: Al Jumuah | C63: 28
A64: 63 | B64: Al Munafiqun | C64: 28
A65: 64 | B65: At Taghobun | C65: 28
A66: 65 | B66: At Talaq | C66: 28
A67: 66 | B67: At Tahrim | C67: 28
A68: 67 | B68: Al Mulk | C68: 29
A69: 68 | B69: Al Qalam | C69: 29
A70: 69 | B70: Al Haqqah | C70: 29
A71: 70 | B71: Al Ma'Arij | C71: 29
A72: 71 | B72: Nuh | C72: 29
A73: 72 | B73: Al Jin | C73: 29
A74: 73 | B74: Al Muzammil | C74: 29
... A115: 114 | B115: An Nas | C115: 30
